Workbook

Sheet Owners
A1: owner_id | B1: first_name | C1: last_name | D1: phone | E1: email | F1: city | G1: street | H1: postal_code
A2: 1 | B2: Jan | C2: Kowalski | D2: 123456789 | E2: jan@gmail.com | F2: Kraków | G2: ul. Długa 10 | H2: 30-011
A3: 2 | B3: Anna | C3: Nowak | D3: 987654321 | E3: anna@gmail.com | F3: Katowice | G3: ul. Znajoma 5 | H3: 40-002
A4: 3 | B4: Piotr | C4: Zieliński | D4: 222111333 | F4: Kraków | G4: ul. Szeroka 8 | H4: 30-111
A5: 4 | B5: Marzena | C5: Mazur | D5: 987654311 | E5: m.mazur12@wp.pl | F5: Niepołomice | G5: ul. Polna 15 | H5: 35-102
A6: 5 | B6: Ewelina | C6: Wójcik | D6: 123654321 | E6: ewelina.w@gmail.com | F6: Kraków | G6: ul. Krawiecka 88 | H6: 30-123
A7: 6 | B7: Tomasz | C7: Baran | D7: 432154321 | F7: Kraków | G7: ul. Brzozowa 4 | H7: 31-112
A8: 7 | B8: Robert | C8: Dąbrowski | D8: 121254321 | E8: r.dabrowski@onet.pl | F8: Katowice | G8: ul. Sosnowa 11 | H8: 40-111
A9: 8 | B9: Katarzyna | C9: Niewiadoma | D9: 795132111 | E9: kat.niew@gmail.com | F9: Słomniki | G9: ul. Krakowska 22 | H9: 36-321
A10: 9 | B10: Julia | C10: Malarczyk | D10: 771257327 | F10: Kraków | G10: aleja 29 listopada 32 | H10: 31-452
A11: 10 | B11: Adrian | C11: Małysz | D11: 721357428 | F11: Zielonki | G11: ul. Krakowskie Przedmieście 55 | H11: 32-078
A12: 11 | B12: Magdalena | C12: Kowalczyk | D12: 601111222 | E12: magda.k@gmail.com | F12: Kraków | G12: ul. Wiślna 3 | H12: 30-015
A13: 12 | B13: Krzysztof | C13: Wiśniewski | D13: 602222333 | F13: Wieliczka | G13: ul. Górnicza 7 | H13: 32-020
A14: 13 | B14: Agnieszka | C14: Pawlak | D14: 603333444 | E14: a.pawlak@wp.pl | F14: Kraków | G14: ul. Józefińska 12 | H14: 30-530
A15: 14 | B15: Marcin | C15: Krawczyk | D15: 604444555 | E15: marcin.kr@onet.pl | F15: Myślenice | G15: ul. Słoneczna 19 | H15: 32-400
A16: 15 | B16: Barbara | C16: Adamczyk | D16: 605555666 | E16: b.adamczyk@gmail.com | F16: Kraków | G16: ul. Rakowicka 44 | H16: 31-510
A17: 16 | B17: Łukasz | C17: Jabłoński | D17: 606666777 | F17: Skawina | G17: ul. Energetyków 8 | H17: 32-050
A18: 17 | B18: Monika | C18: Woźniak | D18: 607777888 | E18: monika.w@gmail.com | F18: Kraków | G18: ul. Prądnicka 67 | H18: 31-202
A19: 18 | B19: Grzegorz | C19: Zając | D19: 608888999 | E19: g.zajac@interia.pl | F19: Niepołomice | G19: ul. Parkowa 3 | H19: 35-102
A20: 19 | B20: Natalia | C20: Kowalska | D20: 609999000 | E20: natalia.kow@gmail.com | F20: Kraków | G20: ul. Lipowa 21 | H20: 30-702
A21: 20 | B21: Damian | C21: Piotrowicz | D21: 610101010 | F21: Zabierzów | G21: ul. Kolejowa 5 | H21: 32-080
A22: 21 | B22: Sylwia | C22: Michalska | D22: 611111111 | E22: s.michalska@wp.pl | F22: Kraków | G22: ul. Botaniczna 9 | H22: 31-503
A23: 22 | B23: Rafał | C23: Sikora | D23: 612121212 | E23: rafal.sikora@gmail.com | F23: Wieliczka | G23: ul. Zamkowa 14 | H23: 32-020
A24: 23 | B24: Dorota | C24: Pietrzak | D24: 613131313 | F24: Kraków | G24: ul. Łagiewnicka 55 | H24: 30-417
A25: 24 | B25: Wojciech | C25: Grabowski | D25: 614141414 | E25: w.grabowski@onet.pl | F25: Nowy Targ | G25: ul. Waksmundzka 2 | H25: 34-400
A26: 25 | B26: Justyna | C26: Nowicka | D26: 615151515 | E26: justyna.now@gmail.com | F26: Kraków | G26: ul. Fieldorfa 11 | H26: 30-960
A27: 26 | B27: Sławomir | C27: Czarnecki | D27: 616161616 | F27: Chrzanów | G27: ul. Kusocińskiego 4 | H27: 32-500
A28: 27 | B28: Paulina | C28: Jaworska | D28: 617171717 | E28: p.jaworska@gmail.com | F28: Kraków | G28: ul. Bieżanowska 88 | H28: 30-826
A29: 28 | B29: Irena | C29: Wieczorek | D29: 618181818 | E29: i.wieczorek@wp.pl | F29: Dobczyce | G29: ul. Rynek 7 | H29: 32-410
A30: 29 | B30: Mateusz | C30: Lewandowski | D30: 619191919 | E30: mateusz.l@gmail.com | F30: Kraków | G30: ul. Kolberga 3 | H30: 31-155
A31: 30 | B31: Halina | C31: Kamińska | D31: 620202020 | F31: Kraków | G31: ul. Opolska 22 | H31: 31-323

Sheet Pets
A1: animal_id | B1: name | C1: species | D1: breed | E1: birth_date | F1: weight | G1: gender | H1: owner_id
A2: 1 | B2: Rex | C2: pies | D2: labrador | E2: 2020-05-10 | F2: 30.5 | G2: samiec | H2: 1
A3: 2 | B3: Mruczek | C3: kot | D3: dachowiec | F3: 4.2 | G3: samiec | H3: 2
A4: 3 | B4: Bella | C4: pies | D4: buldog | E4: 2023-04-01 | F4: 12 | G4: samica | H4: 1
A5: 4 | B5: Kropka | C5: kot | D5: perski | E5: 2019-11-05 | F5: 3.8 | G5: samica | H5: 3
A6: 5 | B6: Kruszynka | C6: chomik | G6: samica | H6: 4
A7: 6 | B7: Cynamon | C7: kot | D7: dachowiec | F7: 4 | G7: samiec | H7: 5
A8: 7 | B8: Puszek | C8: kot | D8: ragdoll | E8: 2024-05-12 | F8: 4.7 | G8: samiec | H8: 6
A9: 8 | B9: Mamba | C9: kot | D9: bombajski | E9: 2023-04-20 | F9: 4 | G9: samica | H9: 6
A10: 9 | B10: Maks | C10: pies | F10: 11 | G10: samiec | H10: 7
A11: 10 | B11: Kulka | C11: chomik | F11: 0.38 | G11: samica | H11: 8
A12: 11 | B12: Pasztecik | C12: chomik | F12: 0.45 | G12: samiec | H12: 8
A13: 12 | B13: Azor | C13: pies | D13: kundel | F13: 15.32 | G13: samiec | H13: 9
A14: 13 | B14: Burek | C14: pies | D14: owczarek | E14: 2019-03-15 | F14: 28 | G14: samiec | H14: 1
A15: 14 | B15: Luna | C15: kot | D15: brytyjski | E15: 2021-07-20 | F15: 4.5 | G15: samica | H15: 2
A16: 15 | B16: Tygrys | C16: kot | D16: dachowiec | E16: 2020-01-10 | F16: 5.1 | G16: samiec | H16: 2
A17: 16 | B17: Zefir | C17: pies | D17: beagle | E17: 2022-06-01 | F17: 10.2 | G17: samiec | H17: 3
A18: 17 | B18: Loki | C18: kot | D18: dachowiec | E18: 2023-02-14 | F18: 3.9 | G18: samiec | H18: 4
A19: 18 | B19: Śnieżka | C19: królik | E19: 2022-10-05 | F19: 1.8 | G19: samica | H19: 4
A20: 19 | B20: Hania | C20: pies | D20: shih tzu | E20: 2021-11-30 | F20: 6.5 | G20: samica | H20: 5
A21: 20 | B21: Perełka | C21: kot | D21: syberyjski | E21: 2020-08-12 | F21: 5.8 | G21: samica | H21: 5
A22: 21 | B22: Gniewko | C22: pies | D22: owczarek | E22: 2018-05-20 | F22: 32 | G22: samiec | H22: 6
A23: 22 | B23: Zara | C23: pies | D23: doberman | E23: 2020-09-25 | F23: 33.5 | G23: samica | H23: 7
A24: 23 | B24: Czesia | C24: kot | D24: dachowiec | F24: 3.4 | G24: samica | H24: 7
A25: 24 | B25: Gucio | C25: pies | D25: corgi | E25: 2022-12-01 | F25: 13 | G25: samiec | H25: 8
A26: 25 | B26: Basia | C26: pies | D26: golden retriever | E26: 2021-03-18 | F26: 27.5 | G26: samica | H26: 9
A27: 26 | B27: Tofik | C27: pies | D27: labrador | E27: 2020-11-11 | F27: 29 | G27: samiec | H27: 10
A28: 27 | B28: Lila | C28: kot | D28: siamski | E28: 2022-04-07 | F28: 3.6 | G28: samica | H28: 11
A29: 28 | B29: Bruno | C29: pies | D29: boxer | E29: 2019-08-22 | F29: 30 | G29: samiec | H29: 11
A30: 29 | B30: Złotko | C30: chomik | F30: 0.42 | G30: samiec | H30: 11
A31: 30 | B31: Atlas | C31: pies | D31: nowofundland | E31: 2018-12-15 | F31: 58 | G31: samiec | H31: 12
A32: 31 | B32: Ruda | C32: kot | D32: maine coon | E32: 2021-05-30 | F32: 6.2 | G32: samica | H32: 12
A33: 32 | B33: Zizi | C33: papuga | E33: 2020-01-01 | F33: 0.32 | G33: samica | H33: 13
A34: 33 | B34: Balbinka | C34: kot | D34: dachowiec | E34: 2022-07-14 | F34: 4.1 | G34: samica | H34: 13
A35: 34 | B35: Reksio | C35: pies | D35: dalmatyńczyk | E35: 2021-02-28 | F35: 24 | G35: samiec | H35: 13
A36: 35 | B36: Nero | C36: pies | D36: rottweiler | E36: 2020-06-10 | F36: 45 | G36: samiec | H36: 14
A37: 36 | B37: Kleopatra | C37: kot | D37: egipski mau | E37: 2023-01-15 | F37: 3.7 | G37: samica | H37: 14
A38: 37 | B38: Fifi | C38: pies | D38: chihuahua | E38: 2021-09-05 | F38: 2.8 | G38: samica | H38: 15
A39: 38 | B39: Miszka | C39: chomik | F39: 0.4 | G39: samica | H39: 15
A40: 39 | B40: Max | C40: pies | D40: husky | E40: 2019-07-20 | F40: 26 | G40: samiec | H40: 16
...

Sheet Vets
A1: vet_id | B1: first_name | C1: last_name | D1: specialization | E1: phone | F1: hire_date | G1: FullName
A2: 1 | B2: Marek | C2: Nowak | D2: chirurgia | E2: 791227333 | F2: 2015-03-01 | G2: =Vets[[#This Row],[first_name]] & " " & Vets[[#This Row],[last_name]] -> Marek Nowak
A3: 2 | B3: Ewa | C3: Lis | D3: dermatologia | E3: 324855166 | F3: 2020-06-15 | G3: =Vets[[#This Row],[first_name]] & " " & Vets[[#This Row],[last_name]] -> Ewa Lis
A4: 3 | B4: Tomasz | C4: Kaczmarek | D4: ortopedia | E4: 127883919 | F4: 2018-09-10 | G4: =Vets[[#This Row],[first_name]] & " " & Vets[[#This Row],[last_name]] -> Tomasz Kaczmarek | K4: Etykiety wierszy | L4: Suma z vet_id
A5: 4 | B5: Anna | C5: Wójcik | D5: radiologia | E5: 772333444 | F5: 2019-01-20 | G5: =Vets[[#This Row],[first_name]] & " " & Vets[[#This Row],[last_name]] -> Anna Wójcik | K5: Anna | L5: 4
A6: 5 | B6: Paweł | C6: Mazur | D6: asystent weterynarii | E6: 755688717 | F6: 2019-11-05 | G6: =Vets[[#This Row],[first_name]] & " " & Vets[[#This Row],[last_name]] -> Paweł Mazur | K6: Wójcik | L6: 4
A7: 6 | B7: Janusz | C7: Szymański | D7: kardiologia | E7: 744628788 | F7: 2018-10-15 | G7: =Vets[[#This Row],[first_name]] & " " & Vets[[#This Row],[last_name]] -> Janusz Szymański | K7: 2019-01-20 | L7: 4
K8: Anna Wójcik | L8: 4
K9: 772333444 | L9: 4
K10: radiologia | L10: 4
K11: Ewa | L11: 2
K12: Lis | L12: 2
K13: 2020-06-15 | L13: 2
K14: Ewa Lis | L14: 2
K15: 324855166 | L15: 2
K16: dermatologia | L16: 2
K17: Janusz | L17: 6
K18: Szymański | L18: 6
K19: 2018-10-15 | L19: 6
... K41: Suma końcowa | L41: 21

Sheet Visits
A1: visit_id | B1: animal_id | C1: vet_id | D1: visit_date | E1: reason | F1: notes | G1: status | H1: is_visit
A2: 1 | B2: 1 | C2: 5 | D2: 45757.417 | E2: szczepienie | F2: brak uwag | G2: zakończona | H2: =IF(AND(B2<>"",G2="zakończona"),"TAK","NIE") -> TAK
A3: 2 | B3: 2 | C3: 2 | D3: 45758.5 | E3: alergia | F3: wysypka na skórze | G3: zakończona | H3: =IF(AND(B3<>"",G3="zakończona"),"TAK","NIE") -> TAK
A4: 3 | B4: 3 | C4: 1 | D4: 45762.375 | E4: kontrola | G4: zakończona | H4: =IF(AND(B4<>"",G4="zakończona"),"TAK","NIE") -> TAK
A5: 4 | B5: 4 | C5: 3 | D5: 45763.458 | E5: uraz łapy | F5: lekkie kulawienie | G5: zakończona | H5: =IF(AND(B5<>"",G5="zakończona"),"TAK","NIE") -> TAK
A6: 5 | B6: 5 | C6: 1 | D6: 45793.542 | E6: operacja | F6: usunięcie guza | G6: zakończona | H6: =IF(AND(B6<>"",G6="zakończona"),"TAK","NIE") -> TAK
A7: 6 | B7: 6 | D7: 45795.583 | E7: badanie ogólne | G7: anulowana | H7: =IF(AND(B7<>"",G7="zakończona"),"TAK","NIE") -> NIE
A8: 7 | B8: 7 | C8: 4 | D8: 45793.458 | E8: diagnostyka | F8: badanie krwi oraz badanie ogólne | G8: zakończona | H8: =IF(AND(B8<>"",G8="zakończona"),"TAK","NIE") -> TAK
A9: 8 | B9: 8 | C9: 4 | D9: 45795.583 | E9: badanie ogólne | G9: anulowana | H9: =IF(AND(B9<>"",G9="zakończona"),"TAK","NIE") -> NIE
A10: 9 | B10: 9 | C10: 3 | D10: 45793.458 | E10: uraz łapy | F10: uraz spowodowany niefortunnym skokiem | G10: zakończona | H10: =IF(AND(B10<>"",G10="zakończona"),"TAK","NIE") -> TAK
A11: 10 | B11: 10 | C11: 1 | D11: 45795.583 | E11: badanie ogólne | G11: zakończona | H11: =IF(AND(B11<>"",G11="zakończona"),"TAK","NIE") -> TAK
A12: 11 | B12: 11 | C12: 5 | D12: 45797.562 | E12: badanie ogólne | F12: brak uwag | G12: zakończona | H12: =IF(AND(B12<>"",G12="zakończona"),"TAK","NIE") -> TAK
A13: 12 | B13: 12 | C13: 5 | D13: 45798.417 | E13: szczepienie | G13: zakończona | H13: =IF(AND(B13<>"",G13="zakończona"),"TAK","NIE") -> TAK
A14: 13 | B14: 13 | C14: 1 | D14: 45798.479 | E14: kontrola - opatrzenie rany | F14: rana w fazie gojenia | G14: zakończona | H14: =IF(AND(B14<>"",G14="zakończona"),"TAK","NIE") -> TAK
A15: 14 | B15: 4 | C15: 3 | D15: 45799.417 | E15: kontrola - uraz łapy | F15: lekkie kulawienie | G15: zakończona | H15: =IF(AND(B15<>"",G15="zakończona"),"TAK","NIE") -> TAK
A16: 15 | B16: 9 | C16: 1 | D16: 45799.458 | E16: kontrola - uraz łapy | F16: uraz spowodowany niefortunnym skokiem | G16: zakończona | H16: =IF(AND(B16<>"",G16="zakończona"),"TAK","NIE") -> TAK
A17: 16 | B17: 5 | C17: 1 | D17: 45799.5 | E17: kontrola po operacji chomika | G17: zakończona | H17: =IF(AND(B17<>"",G17="zakończona"),"TAK","NIE") -> TAK
A18: 17 | B18: 14 | C18: 1 | D18: 45749.375 | E18: szczepienie | F18: szczepionka przeciw parwowirozie | G18: zakończona | H18: =IF(AND(B18<>"",G18="zakończona"),"TAK","NIE") -> TAK
A19: 18 | B19: 15 | C19: 2 | D19: 45749.438 | E19: kontrola skóry | F19: alergia kontaktowa - podrażnienie | G19: zakończona | H19: =IF(AND(B19<>"",G19="zakończona"),"TAK","NIE") -> TAK
A20: 19 | B20: 16 | C20: 3 | D20: 45750.458 | E20: uraz | F20: skręcenie łapy przedniej | G20: zakończona | H20: =IF(AND(B20<>"",G20="zakończona"),"TAK","NIE") -> TAK
A21: 20 | B21: 17 | C21: 1 | D21: 45750.5 | E21: kastracja | F21: zabieg kastracji - przebieg pomyślny | G21: zakończona | H21: =IF(AND(B21<>"",G21="zakończona"),"TAK","NIE") -> TAK
A22: 21 | B22: 18 | C22: 4 | D22: 45751.396 | E22: badanie ogólne | F22: zwierzę w dobrej kondycji | G22: zakończona | H22: =IF(AND(B22<>"",G22="zakończona"),"TAK","NIE") -> TAK
A23: 22 | B23: 19 | C23: 5 | D23: 45751.458 | E23: szczepienie | F23: szczepionka mix podstawowy | G23: zakończona | H23: =IF(AND(B23<>"",G23="zakończona"),"TAK","NIE") -> TAK
A24: 23 | B24: 20 | C24: 2 | D24: 45754.417 | E24: alergia | F24: nadwrażliwość pokarmowa | G24: zakończona | H24: =IF(AND(B24<>"",G24="zakończona"),"TAK","NIE") -> TAK
A25: 24 | B25: 21 | C25: 3 | D25: 45754.542 | E25: uraz łapy | F25: złamanie palca - szyna gipsowa | G25: zakończona | H25: =IF(AND(B25<>"",G25="zakończona"),"TAK","NIE") -> TAK
A26: 25 | B26: 22 | C26: 6 | D26: 45755.375 | E26: badanie serca | F26: EKG wykonane, brak nieprawidłowości | G26: zakończona | H26: =IF(AND(B26<>"",G26="zakończona"),"TAK","NIE") -> TAK
A27: 26 | B27: 23 | C27: 1 | D27: 45755.438 | E27: sterylizacja | F27: zabieg sterylizacji - bez komplikacji | G27: zakończona | H27: =IF(AND(B27<>"",G27="zakończona"),"TAK","NIE") -> TAK
A28: 27 | B28: 24 | C28: 4 | D28: 45756.458 | E28: diagnostyka | F28: badanie krwi i RTG klatki piersiowej | G28: zakończona | H28: =IF(AND(B28<>"",G28="zakończona"),"TAK","NIE") -> TAK
A29: 28 | B29: 25 | C29: 2 | D29: 45756.521 | E29: kontrola | F29: kontrola po alergii - poprawa | G29: zakończona | H29: =IF(AND(B29<>"",G29="zakończona"),"TAK","NIE") -> TAK
... A66: 65 | B66: 62 | C66: 4 | D66: 45791.375 | E66: diagnostyka | F66: badanie krwi pełne | G66: zakończona | H66: =IF(AND(B66<>"",G66="zakończona"),"TAK","NIE") -> TAK
A67: 66 | B67: 63 | D67: 45791.458 | E67: badanie ogólne | G67: anulowana | H67: =IF(AND(B67<>"",G67="zakończona"),"TAK","NIE") -> NIE
A68: 67 | B68: 64 | D68: 45792.417 | E68: szczepienie | G68: anulowana | H68: =IF(AND(B68<>"",G68="zakończona"),"TAK","NIE") -> NIE
A69: 68 | B69: 65 | D69: 45792.5 | E69: kontrola | G69: anulowana | H69: =IF(AND(B69<>"",G69="zakończona"),"TAK","NIE") -> NIE
A70: 69 | B70: 66 | C70: 1 | D70: 45796.375 | E70: chirurgia | F70: biopsja guza | G70: zakończona | H70: =IF(AND(B70<>"",G70="zakończona"),"TAK","NIE") -> TAK
A71: 70 | B71: 67 | C71: 2 | D71: 45796.438 | E71: kontrola | F71: kontrola po leczeniu alergii | G71: zakończona | H71: =IF(AND(B71<>"",G71="zakończona"),"TAK","NIE") -> TAK
A72: 71 | B72: 68 | C72: 3 | D72: 45797.458 | E72: ortopedia | F72: ocena chodu po urazie | G72: zakończona | H72: =IF(AND(B72<>"",G72="zakończona"),"TAK","NIE") -> TAK
A73: 72 | B73: 69 | C73: 5 | D73: 45798.396 | E73: badanie ogólne | F73: profilaktyka - wiek 1 rok | G73: zakończona | H73: =IF(AND(B73<>"",G73="zakończona"),"TAK","NIE") -> TAK
A74: 73 | B74: 70 | C74: 6 | D74: 45800.417 | E74: kardiologia | F74: EKG - nieznaczne odchylenia | G74: zakończona | H74: =IF(AND(B74<>"",G74="zakończona"),"TAK","NIE") -> TAK
A75: 74 | B75: 71 | D75: 45800.5 | E75: badanie ogólne | G75: anulowana | H75: =IF(AND(B75<>"",G75="zakończona"),"TAK","NIE") -> NIE
A76: 75 | B76: 72 | D76: 45803.417 | E76: szczepienie | G76: anulowana | H76: =IF(AND(B76<>"",G76="zakończona"),"TAK","NIE") -> NIE
...

Sheet Treatments
A1: treatment_id | B1: visit_id | C1: name | D1: description | E1: notes | F1: duration | G1: cost | H1: treatmentCategory
A2: 1 | B2: 1 | C2: szczepienie | D2: podanie szczepionki przeciw wściekliźnie | E2: Zwierzę było spokojne. Podano szczepionkę. Brak reakcji niepożądanych. Zalecana kontrola za rok. | F2: 40 | G2: 50 | H2: =IF(ISNUMBER(FIND("szczep",C2)),"Szczepienie", IF(ISNUMBER(FIND("kardio",C2)),"Kardiologia", IF(ISNUMBER(FIND("ortoped",C2)),"Ortopedia", IF(ISNUMBER(FIND("uraz",C2)),"Ortopedia", IF(ISNUMBER(FIND("dermat",C2)),"Dermatologia", IF(ISNUMBER(FIND("chirurg",C2)),"Chirurgia", IF(ISNUMBER(FIND("operac",C2)),"Chirurgia", IF(ISNUMBER(FIND("diagnost",C2)),"Diagnostyka", IF(ISNUMBER(FIND("odrobacz",C2)),"Odrobaczanie", IF(ISNUMBER(FIND("kontrola",C2)),"Kontrola", IF(ISNUMBER(FIND("alergia",C2)),"Dermatologia", IF(ISNUMBER(FIND("dieta",C2)),"Dieta", "Badanie ogólne")))))))))))) -> Szczepienie
A3: 2 | B3: 2 | C3: alergia | D3: podanie leków na alergię | E3: Wysypka zniknęła częściowo. Zalecana kontrola po tygodniu. Podano lek przeciwhistaminowy. | F3: 30 | G3: 40 | H3: =IF(ISNUMBER(FIND("szczep",C3)),"Szczepienie", IF(ISNUMBER(FIND("kardio",C3)),"Kardiologia", IF(ISNUMBER(FIND("ortoped",C3)),"Ortopedia", IF(ISNUMBER(FIND("uraz",C3)),"Ortopedia", IF(ISNUMBER(FIND("dermat",C3)),"Dermatologia", IF(ISNUMBER(FIND("chirurg",C3)),"Chirurgia", IF(ISNUMBER(FIND("operac",C3)),"Chirurgia", IF(ISNUMBER(FIND("diagnost",C3)),"Diagnostyka", IF(ISNUMBER(FIND("odrobacz",C3)),"Odrobaczanie", IF(ISNUMBER(FIND("kontrola",C3)),"Kontrola", IF(ISNUMBER(FIND("alergia",C3)),"Dermatologia", IF(ISNUMBER(FIND("dieta",C3)),"Dieta", "Badanie ogólne")))))))))))) -> Dermatologia
A4: 3 | B4: 3 | C4: kontrola | D4: kontrola stanu zdrowia | E4: Zwierzę w dobrej kondycji. Brak uwag. | F4: 60 | G4: 30 | H4: =IF(ISNUMBER(FIND("szczep",C4)),"Szczepienie", IF(ISNUMBER(FIND("kardio",C4)),"Kardiologia", IF(ISNUMBER(FIND("ortoped",C4)),"Ortopedia", IF(ISNUMBER(FIND("uraz",C4)),"Ortopedia", IF(ISNUMBER(FIND("dermat",C4)),"Dermatologia", IF(ISNUMBER(FIND("chirurg",C4)),"Chirurgia", IF(ISNUMBER(FIND("operac",C4)),"Chirurgia", IF(ISNUMBER(FIND("diagnost",C4)),"Diagnostyka", IF(ISNUMBER(FIND("odrobacz",C4)),"Odrobaczanie", IF(ISNUMBER(FIND("kontrola",C4)),"Kontrola", IF(ISNUMBER(FIND("alergia",C4)),"Dermatologia", IF(ISNUMBER(FIND("dieta",C4)),"Dieta", "Badanie ogólne")))))))))))) -> Kontrola
A5: 4 | B5: 4 | C5: uraz łapy | D5: wykonanie zdjęcia RTG łapy | E5: Rana oczyszczona i zabandażowana. Pacjent był niespokojny, zalecano ograniczenie ruchu przez 3 dni. | F5: 90 | G5: 90 | H5: =IF(ISNUMBER(FIND("szczep",C5)),"Szczepienie", IF(ISNUMBER(FIND("kardio",C5)),"Kardiologia", IF(ISNUMBER(FIND("ortoped",C5)),"Ortopedia", IF(ISNUMBER(FIND("uraz",C5)),"Ortopedia", IF(ISNUMBER(FIND("dermat",C5)),"Dermatologia", IF(ISNUMBER(FIND("chirurg",C5)),"Chirurgia", IF(ISNUMBER(FIND("operac",C5)),"Chirurgia", IF(ISNUMBER(FIND("diagnost",C5)),"Diagnostyka", IF(ISNUMBER(FIND("odrobacz",C5)),"Odrobaczanie", IF(ISNUMBER(FIND("kontrola",C5)),"Kontrola", IF(ISNUMBER(FIND("alergia",C5)),"Dermatologia", IF(ISNUMBER(FIND("dieta",C5)),"Dieta", "Badanie ogólne")))))))))))) -> Ortopedia
A6: 5 | B6: 5 | C6: operacja | D6: Przeprowadzono operacje guza u chomika. Pacjent był pod narkozą. Operacja przebiegła pomyślnie. Zalecono odpoczynek i leki przeciwbólowe. | F6: 120 | G6: 150 | H6: =IF(ISNUMBER(FIND("szczep",C6)),"Szczepienie", IF(ISNUMBER(FIND("kardio",C6)),"Kardiologia", IF(ISNUMBER(FIND("ortoped",C6)),"Ortopedia", IF(ISNUMBER(FIND("uraz",C6)),"Ortopedia", IF(ISNUMBER(FIND("dermat",C6)),"Dermatologia", IF(ISNUMBER(FIND("chirurg",C6)),"Chirurgia", IF(ISNUMBER(FIND("operac",C6)),"Chirurgia", IF(ISNUMBER(FIND("diagnost",C6)),"Diagnostyka", IF(ISNUMBER(FIND("odrobacz",C6)),"Odrobaczanie", IF(ISNUMBER(FIND("kontrola",C6)),"Kontrola", IF(ISNUMBER(FIND("alergia",C6)),"Dermatologia", IF(ISNUMBER(FIND("dieta",C6)),"Dieta", "Badanie ogólne")))))))))))) -> Chirurgia
A7: 6 | B7: 7 | C7: diagnostyka | D7: Standardowe badanie ogólne. | E7: Informacja o profilaktyce. | F7: 60 | G7: 15 | H7: =IF(ISNUMBER(FIND("szczep",C7)),"Szczepienie", IF(ISNUMBER(FIND("kardio",C7)),"Kardiologia", IF(ISNUMBER(FIND("ortoped",C7)),"Ortopedia", IF(ISNUMBER(FIND("uraz",C7)),"Ortopedia", IF(ISNUMBER(FIND("dermat",C7)),"Dermatologia", IF(ISNUMBER(FIND("chirurg",C7)),"Chirurgia", IF(ISNUMBER(FIND("operac",C7)),"Chirurgia", IF(ISNUMBER(FIND("diagnost",C7)),"Diagnostyka", IF(ISNUMBER(FIND("odrobacz",C7)),"Odrobaczanie", IF(ISNUMBER(FIND("kontrola",C7)),"Kontrola", IF(ISNUMBER(FIND("alergia",C7)),"Dermatologia", IF(ISNUMBER(FIND("dieta",C7)),"Dieta", "Badanie ogólne")))))))))))) -> Diagnostyka
A8: 7 | B8: 9 | C8: uraz łapy | D8: Oczyszczenie i zdezynfekowanie rany. Założenie opatrunku i stabilizacja kończyny. | E8: Uraz spowodowany niefortunnym skokiem. Rana oczyszczona i zabandażowana. Pacjent był niespokojny, zalecano ograniczenie ruchu przez 3 dni. Kontrola za tydzień. | F8: 100 | G8: 110 | H8: =IF(ISNUMBER(FIND("szczep",C8)),"Szczepienie", IF(ISNUMBER(FIND("kardio",C8)),"Kardiologia", IF(ISNUMBER(FIND("ortoped",C8)),"Ortopedia", IF(ISNUMBER(FIND("uraz",C8)),"Ortopedia", IF(ISNUMBER(FIND("dermat",C8)),"Dermatologia", IF(ISNUMBER(FIND("chirurg",C8)),"Chirurgia", IF(ISNUMBER(FIND("operac",C8)),"Chirurgia", IF(ISNUMBER(FIND("diagnost",C8)),"Diagnostyka", IF(ISNUMBER(FIND("odrobacz",C8)),"Odrobaczanie", IF(ISNUMBER(FIND("kontrola",C8)),"Kontrola", IF(ISNUMBER(FIND("alergia",C8)),"Dermatologia", IF(ISNUMBER(FIND("dieta",C8)),"Dieta", "Badanie ogólne")))))))))))) -> Ortopedia
A9: 8 | B9: 10 | C9: badanie ogólne | D9: Standardowe badanie kontrolne zwierzęcia. | E9: Pacjent zdrowy. Zalecono kontrolę profilaktyczną za 6 miesięcy. | F9: 30 | G9: 60 | H9: =IF(ISNUMBER(FIND("szczep",C9)),"Szczepienie", IF(ISNUMBER(FIND("kardio",C9)),"Kardiologia", IF(ISNUMBER(FIND("ortoped",C9)),"Ortopedia", IF(ISNUMBER(FIND("uraz",C9)),"Ortopedia", IF(ISNUMBER(FIND("dermat",C9)),"Dermatologia", IF(ISNUMBER(FIND("chirurg",C9)),"Chirurgia", IF(ISNUMBER(FIND("operac",C9)),"Chirurgia", IF(ISNUMBER(FIND("diagnost",C9)),"Diagnostyka", IF(ISNUMBER(FIND("odrobacz",C9)),"Odrobaczanie", IF(ISNUMBER(FIND("kontrola",C9)),"Kontrola", IF(ISNUMBER(FIND("alergia",C9)),"Dermatologia", IF(ISNUMBER(FIND("dieta",C9)),"Dieta", "Badanie ogólne")))))))))))) -> Badanie ogólne
A10: 9 | B10: 11 | C10: badanie ogólne | D10: Ocena kondycji oraz parametrów życiowych. | E10: Brak nieprawidłowości. | F10: 25 | G10: 50 | H10: =IF(ISNUMBER(FIND("szczep",C10)),"Szczepienie", IF(ISNUMBER(FIND("kardio",C10)),"Kardiologia", IF(ISNUMBER(FIND("ortoped",C10)),"Ortopedia", IF(ISNUMBER(FIND("uraz",C10)),"Ortopedia", IF(ISNUMBER(FIND("dermat",C10)),"Dermatologia", IF(ISNUMBER(FIND("chirurg",C10)),"Chirurgia", IF(ISNUMBER(FIND("operac",C10)),"Chirurgia", IF(ISNUMBER(FIND("diagnost",C10)),"Diagnostyka", IF(ISNUMBER(FIND("odrobacz",C10)),"Odrobaczanie", IF(ISNUMBER(FIND("kontrola",C10)),"Kontrola", IF(ISNUMBER(FIND("alergia",C10)),"Dermatologia", IF(ISNUMBER(FIND("dieta",C10)),"Dieta", "Badanie ogólne")))))))))))) -> Badanie ogólne
A11: 10 | B11: 12 | C11: szczepienie | D11: Podanie szczepionki przeciw wściekliźnie. | E11: Brak reakcji poszczepiennej. | F11: 20 | G11: 70 | H11: =IF(ISNUMBER(FIND("szczep",C11)),"Szczepienie", IF(ISNUMBER(FIND("kardio",C11)),"Kardiologia", IF(ISNUMBER(FIND("ortoped",C11)),"Ortopedia", IF(ISNUMBER(FIND("uraz",C11)),"Ortopedia", IF(ISNUMBER(FIND("dermat",C11)),"Dermatologia", IF(ISNUMBER(FIND("chirurg",C11)),"Chirurgia", IF(ISNUMBER(FIND("operac",C11)),"Chirurgia", IF(ISNUMBER(FIND("diagnost",C11)),"Diagnostyka", IF(ISNUMBER(FIND("odrobacz",C11)),"Odrobaczanie", IF(ISNUMBER(FIND("kontrola",C11)),"Kontrola", IF(ISNUMBER(FIND("alergia",C11)),"Dermatologia", IF(ISNUMBER(FIND("dieta",C11)),"Dieta", "Badanie ogólne")))))))))))) -> Szczepienie
A12: 11 | B12: 13 | C12: kontrola rany | D12: Kontrola procesu gojenia oraz wymiana opatrunku. | E12: Rana goi się prawidłowo. Zmieniono opatrunek. | F12: 35 | G12: 80 | H12: =IF(ISNUMBER(FIND("szczep",C12)),"Szczepienie", IF(ISNUMBER(FIND("kardio",C12)),"Kardiologia", IF(ISNUMBER(FIND("ortoped",C12)),"Ortopedia", IF(ISNUMBER(FIND("uraz",C12)),"Ortopedia", IF(ISNUMBER(FIND("dermat",C12)),"Dermatologia", IF(ISNUMBER(FIND("chirurg",C12)),"Chirurgia", IF(ISNUMBER(FIND("operac",C12)),"Chirurgia", IF(ISNUMBER(FIND("diagnost",C12)),"Diagnostyka", IF(ISNUMBER(FIND("odrobacz",C12)),"Odrobaczanie", IF(ISNUMBER(FIND("kontrola",C12)),"Kontrola", IF(ISNUMBER(FIND("alergia",C12)),"Dermatologia", IF(ISNUMBER(FIND("dieta",C12)),"Dieta", "Badanie ogólne")))))))))))) -> Kontrola
A13: 12 | B13: 14 | C13: kontrola ortopedyczna | D13: Kontrola urazu łapy po wcześniejszym leczeniu. | E13: Kulawienie minimalne. Kontynuować ograniczenie ruchu. | F13: 40 | G13: 90 | H13: =IF(ISNUMBER(FIND("szczep",C13)),"Szczepienie", IF(ISNUMBER(FIND("kardio",C13)),"Kardiologia", IF(ISNUMBER(FIND("ortoped",C13)),"Ortopedia", IF(ISNUMBER(FIND("uraz",C13)),"Ortopedia", IF(ISNUMBER(FIND("dermat",C13)),"Dermatologia", IF(ISNUMBER(FIND("chirurg",C13)),"Chirurgia", IF(ISNUMBER(FIND("operac",C13)),"Chirurgia", IF(ISNUMBER(FIND("diagnost",C13)),"Diagnostyka", IF(ISNUMBER(FIND("odrobacz",C13)),"Odrobaczanie", IF(ISNUMBER(FIND("kontrola",C13)),"Kontrola", IF(ISNUMBER(FIND("alergia",C13)),"Dermatologia", IF(ISNUMBER(FIND("dieta",C13)),"Dieta", "Badanie ogólne")))))))))))) -> Ortopedia
A14: 13 | B14: 15 | C14: kontrola urazu | D14: Ocena procesu gojenia kończyny. | E14: Stan stabilny. Opatrunek wymieniony. | F14: 35 | G14: 85 | H14: =IF(ISNUMBER(FIND("szczep",C14)),"Szczepienie", IF(ISNUMBER(FIND("kardio",C14)),"Kardiologia", IF(ISNUMBER(FIND("ortoped",C14)),"Ortopedia", IF(ISNUMBER(FIND("uraz",C14)),"Ortopedia", IF(ISNUMBER(FIND("dermat",C14)),"Dermatologia", IF(ISNUMBER(FIND("chirurg",C14)),"Chirurgia", IF(ISNUMBER(FIND("operac",C14)),"Chirurgia", IF(ISNUMBER(FIND("diagnost",C14)),"Diagnostyka", IF(ISNUMBER(FIND("odrobacz",C14)),"Odrobaczanie", IF(ISNUMBER(FIND("kontrola",C14)),"Kontrola", IF(ISNUMBER(FIND("alergia",C14)),"Dermatologia", IF(ISNUMBER(FIND("dieta",C14)),"Dieta", "Badanie ogólne")))))))))))) -> Ortopedia
A15: 14 | B15: 16 | C15: kontrola pooperacyjna | D15: Kontrola po zabiegu usunięcia guza. | E15: Pacjent w dobrej kondycji. Rana goi się prawidłowo. | F15: 30 | G15: 75 | H15: =IF(ISNUMBER(FIND("szczep",C15)),"Szczepienie", IF(ISNUMBER(FIND("kardio",C15)),"Kardiologia", IF(ISNUMBER(FIND("ortoped",C15)),"Ortopedia", IF(ISNUMBER(FIND("uraz",C15)),"Ortopedia", IF(ISNUMBER(FIND("dermat",C15)),"Dermatologia", IF(ISNUMBER(FIND("chirurg",C15)),"Chirurgia", IF(ISNUMBER(FIND("operac",C15)),"Chirurgia", IF(ISNUMBER(FIND("diagnost",C15)),"Diagnostyka", IF(ISNUMBER(FIND("odrobacz",C15)),"Odrobaczanie", IF(ISNUMBER(FIND("kontrola",C15)),"Kontrola", IF(ISNUMBER(FIND("alergia",C15)),"Dermatologia", IF(ISNUMBER(FIND("dieta",C15)),"Dieta", "Badanie ogólne")))))))))))) -> Chirurgia
A16: 15 | B16: 17 | C16: szczepienie | D16: Podanie szczepionki przeciw parwowirozie i nosówce. | E16: Zwierzę spokojne. Brak reakcji niepożądanych. Zalecane szczepienie przypominające za rok. | F16: 30 | G16: 55 | H16: =IF(ISNUMBER(FIND("szczep",C16)),"Szczepienie", IF(ISNUMBER(FIND("kardio",C16)),"Kardiologia", IF(ISNUMBER(FIND("ortoped",C16)),"Ortopedia", IF(ISNUMBER(FIND("uraz",C16)),"Ortopedia", IF(ISNUMBER(FIND("dermat",C16)),"Dermatologia", IF(ISNUMBER(FIND("chirurg",C16)),"Chirurgia", IF(ISNUMBER(FIND("operac",C16)),"Chirurgia", IF(ISNUMBER(FIND("diagnost",C16)),"Diagnostyka", IF(ISNUMBER(FIND("odrobacz",C16)),"Odrobaczanie", IF(ISNUMBER(FIND("kontrola",C16)),"Kontrola", IF(ISNUMBER(FIND("alergia",C16)),"Dermatologia", IF(ISNUMBER(FIND("dieta",C16)),"Dieta", "Badanie ogólne")))))))))))) -> Szczepienie
A17: 16 | B17: 18 | C17: dermatologia | D17: Ocena zmian skórnych, pobranie próbki do badania. | E17: Alergia kontaktowa potwierdzona. Zalecono eliminację czynnika drażniącego. | F17: 45 | G17: 80 | H17: =IF(ISNUMBER(FIND("szczep",C17)),"Szczepienie", IF(ISNUMBER(FIND("kardio",C17)),"Kardiologia", IF(ISNUMBER(FIND("ortoped",C17)),"Ortopedia", IF(ISNUMBER(FIND("uraz",C17)),"Ortopedia", IF(ISNUMBER(FIND("dermat",C17)),"Dermatologia", IF(ISNUMBER(FIND("chirurg",C17)),"Chirurgia", IF(ISNUMBER(FIND("operac",C17)),"Chirurgia", IF(ISNUMBER(FIND("diagnost",C17)),"Diagnostyka", IF(ISNUMBER(FIND("odrobacz",C17)),"Odrobaczanie", IF(ISNUMBER(FIND("kontrola",C17)),"Kontrola", IF(ISNUMBER(FIND("alergia",C17)),"Dermatologia", IF(ISNUMBER(FIND("dieta",C17)),"Dieta", "Badanie ogólne")))))))))))) -> Dermatologia
A18: 17 | B18: 19 | C18: ortopedia | D18: Badanie i ocena urazu łapy, wykonanie RTG. | E18: Skręcenie I stopnia. Założono stabilizator. Zalecono 5 dni ograniczonego ruchu. | F18: 60 | G18: 120 | H18: =IF(ISNUMBER(FIND("szczep",C18)),"Szczepienie", IF(ISNUMBER(FIND("kardio",C18)),"Kardiologia", IF(ISNUMBER(FIND("ortoped",C18)),"Ortopedia", IF(ISNUMBER(FIND("uraz",C18)),"Ortopedia", IF(ISNUMBER(FIND("dermat",C18)),"Dermatologia", IF(ISNUMBER(FIND("chirurg",C18)),"Chirurgia", IF(ISNUMBER(FIND("operac",C18)),"Chirurgia", IF(ISNUMBER(FIND("diagnost",C18)),"Diagnostyka", IF(ISNUMBER(FIND("odrobacz",C18)),"Odrobaczanie", IF(ISNUMBER(FIND("kontrola",C18)),"Kontrola", IF(ISNUMBER(FIND("alergia",C18)),"Dermatologia", IF(ISNUMBER(FIND("dieta",C18)),"Dieta", "Badanie ogólne")))))))))))) -> Ortopedia
... A148: 147 | B148: 154 | C148: kardiologia | D148: Kontrolne badanie kardiologiczne. | E148: Stan stabilny. Parametry sercowe prawidłowe. | F148: 40 | G148: 120 | H148: =IF(ISNUMBER(FIND("szczep",C148)),"Szczepienie", IF(ISNUMBER(FIND("kardio",C148)),"Kardiologia", IF(ISNUMBER(FIND("ortoped",C148)),"Ortopedia", IF(ISNUMBER(FIND("uraz",C148)),"Ortopedia", IF(ISNUMBER(FIND("dermat",C148)),"Dermatologia", IF(ISNUMBER(FIND("chirurg",C148)),"Chirurgia", IF(ISNUMBER(FIND("operac",C148)),"Chirurgia", IF(ISNUMBER(FIND("diagnost",C148)),"Diagnostyka", IF(ISNUMBER(FIND("odrobacz",C148)),"Odrobaczanie", IF(ISNUMBER(FIND("kontrola",C148)),"Kontrola", IF(ISNUMBER(FIND("alergia",C148)),"Dermatologia", IF(ISNUMBER(FIND("dieta",C148)),"Dieta", "Badanie ogólne")))))))))))) -> Kardiologia

Sheet Prescriptions
A1: prescription_id | B1: treatment_id | C1: medicine_name | D1: dosage | E1: duration_days | F1: notes
A2: 1 | B2: 2 | C2: Dolvit Allergy | D2: 2x dziennie po 1 tabletce | E2: 7 | F2: Podawać po posiłku.
A3: 2 | B3: 4 | C3: RemediCann | D3: 2x dziennie | E3: 10 | F3: Maść przeciwzapalna. Nanieść cienką warstwę na ranę.
A4: 3 | B4: 4 | C4: Meloksykam | D4: 1x dziennie | E4: 5 | F4: Środek przeciwbólowy. Podawać w razie bólu.
A5: 4 | B5: 5 | C5: Antybiotyk VetCure | D5: 2x dziennie po 0.5 ml | E5: 7 | F5: Podawać po jedzeniu. Obserwować stan zwierzęcia.
A6: 5 | B6: 5 | C6: Meloksykam | D6: 1x dziennie | E6: 5 | F6: Podawać zgodnie z zaleceniami lekarza.
A7: 6 | B7: 6 | C7: Dolfos Vetcal D3 | D7: 1x dziennie | E7: 14 | F7: Witamina D. Podawać razem z jedzeniem.
A8: 7 | B8: 7 | C8: Beaphar Wound Maść | D8: 2x dziennie | E8: 10 | F8: Maść łagodzącą stosować na oczyszczoną ranę. Kontrola za tydzień.
A9: 8 | B9: 8 | C9: NexGard Spectra | D9: 1x w miesiącu | E9: 3 | F9: Profilaktyka pcheł i kleszczy. Podawać z jedzeniem.
A10: 9 | B10: 9 | C10: Apoquel | D10: 1x dziennie 5.4 mg | E10: 14 | F10: Lek przeciwświądowy. Podawać rano.
A11: 10 | B11: 9 | C11: Malaseb szampon | D11: 2x w tygodniu | E11: 14 | F11: Myć przez 5 min, spłukać dokładnie.
A12: 11 | B12: 10 | C12: Metacam 1.5 mg/ml | D12: 1x dziennie | E12: 7 | F12: NLPZ - podawać z jedzeniem. Nie przekraczać dawki.
A13: 12 | B13: 10 | C13: Gabapentyna 100 mg | D13: 2x dziennie | E13: 5 | F13: Środek przeciwbólowy neuropatyczny.
... A61: 60 | B61: 109 | C61: Furosemid 10 mg | D61: 1x dziennie | E61: 30 | F61: Dawka zredukowana. Obserwować obrzęki.

Sheet Statystyki
A1: Tabela KPI
A2: Metryka | B2: Wartość
A3: Liczba zabiegów | B3: =COUNT(Treatments!A:A) -> 147
A4: Liczba pacjentów | B4: =COUNT(Pets!A:A) -> 78
A5: Łączny przychód | B5: =SUM(Treatments!F:F) -> 5505
A6: Średni koszt zabiegu | B6: =AVERAGE(Treatments!F:F) -> 37.44898
A7: Najdroższy zabieg | B7: =MAX(Treatments!F:F) -> 180
A8: Najtańszy zabieg | B8: =MIN(Treatments!F:F) -> 15
A9: Anulowane wizyty | B9: =COUNTIF(Visits!G:G,"anulowana") -> 7

Sheet Analiza
K1: species | L1: (Wszystko)
K2: Top pacjenci wg kosztów leczenia | O2: Liczba zabiegów wg kategorii leczenia
A3: Lekarz | B3: Wizyty | C3: Całkowita suma zabiegów | D3: Średni koszt zabiegu | F3: Gatunki | G3: Średnia kosztu zabiegu | H3: Suma z cost | K3: Imiona zwierząt | L3: Całkowita suma | M3: Ilość wizyt | O3: Kategoria leczenia | P3: Ilość | Q3: Całkowita suma
A4: Marek Nowak | B4: 31 | C4: 4175 | D4: 134.67742 | F4: chomik | G4: 112.72727 | H4: 1240 | K4: Zuzia | L4: 335 | M4: 3 | O4: Badanie ogólne | P4: 18 | Q4: 1075
A5: Paweł Mazur | B5: 27 | C5: 2130 | D5: 78.888889 | F5: kot | G5: 91.826923 | H5: 4775 | K5: Ptyś | L5: 1250 | M5: 2 | O5: Chirurgia | P5: 16 | Q5: 4405
A6: Tomasz Kaczmarek | B6: 25 | C6: 3260 | D6: 130.4 | F6: królik | G6: 191.66667 | H6: 1150 | K6: Reksio | L6: 290 | M6: 2 | O6: Dermatologia | P6: 24 | Q6: 1705
A7: Ewa Lis | B7: 25 | C7: 2170 | D7: 86.8 | F7: papuga | G7: 90 | H7: 630 | K7: Czesia | L7: 485 | M7: 2 | O7: Diagnostyka | P7: 15 | Q7: 1625
A8: Anna Wójcik | B8: 20 | C8: 1410 | D8: 70.5 | F8: pies | G8: 103.38028 | H8: 7340 | K8: Puch | L8: 940 | M8: 2 | O8: Dieta | P8: 1 | Q8: 45
A9: Janusz Szymański | B9: 19 | C9: 1990 | D9: 104.73684 | F9: Suma końcowa | G9: 102.95918 | H9: 15135 | K9: Kleks | L9: 360 | M9: 2 | O9: Kardiologia | P9: 18 | Q9: 2420
A10: Suma końcowa | B10: 147 | C10: 15135 | D10: 102.95918 | K10: Śmiga | L10: 325 | M10: 2 | O10: Kontrola | P10: 11 | Q10: 470
K11: Loki | L11: 415 | M11: 2 | O11: Odrobaczanie | P11: 6 | Q11: 205
K12: Atlas | L12: 390 | M12: 2 | O12: Ortopedia | P12: 22 | Q12: 2215
K13: Pistacjo | L13: 380 | M13: 2 | O13: Szczepienie | P13: 16 | Q13: 970
K14: Suma końcowa | L14: 5170 | M14: 21 | O14: Suma końcowa | P14: 147 | Q14: 15135

Sheet tabele pomocnicze
A1: visit_id | B1: vet_id | C1: FullName | D1: cost | E1: treatment_id | H1: visit_id | I1: species | J1: cost | L1: top pacjenci
A2: 1 | B2: 5 | C2: =VLOOKUP(B2,Vets!A:G,7,FALSE) -> Paweł Mazur | D2: =VLOOKUP(E2,Treatments!A:G,7,FALSE) -> 50 | E2: 1 | H2: 1 | I2: =VLOOKUP(VLOOKUP(H2,Visits!A:B,2,FALSE),Pets!A:C,3,FALSE) -> pies | J2: =VLOOKUP(H2,Treatments!B:G,6,FALSE) -> 50 | L2: visit_id | M2: animal_id | N2: petName | O2: cost | P2: species
A3: 2 | B3: 2 | C3: =VLOOKUP(B3,Vets!A:G,7,FALSE) -> Ewa Lis | D3: =VLOOKUP(E3,Treatments!A:G,7,FALSE) -> 40 | E3: 2 | H3: 2 | I3: =VLOOKUP(VLOOKUP(H3,Visits!A:B,2,FALSE),Pets!A:C,3,FALSE) -> kot | J3: =VLOOKUP(H3,Treatments!B:G,6,FALSE) -> 40 | L3: 1 | M3: 1 | N3: =VLOOKUP(M3,Pets!A:B,2,FALSE) -> Rex | O3: =IFERROR(VLOOKUP(L3,Treatments!B:G,6,FALSE),0) -> 50 | P3: =VLOOKUP(M3,Pets!A:C,3,FALSE) -> pies
A4: 3 | B4: 1 | C4: =VLOOKUP(B4,Vets!A:G,7,FALSE) -> Marek Nowak | D4: =VLOOKUP(E4,Treatments!A:G,7,FALSE) -> 30 | E4: 3 | H4: 3 | I4: =VLOOKUP(VLOOKUP(H4,Visits!A:B,2,FALSE),Pets!A:C,3,FALSE) -> pies | J4: =VLOOKUP(H4,Treatments!B:G,6,FALSE) -> 30 | L4: 2 | M4: 2 | N4: =VLOOKUP(M4,Pets!A:B,2,FALSE) -> Mruczek | O4: =IFERROR(VLOOKUP(L4,Treatments!B:G,6,FALSE),0) -> 40 | P4: =VLOOKUP(M4,Pets!A:C,3,FALSE) -> kot
A5: 4 | B5: 3 | C5: =VLOOKUP(B5,Vets!A:G,7,FALSE) -> Tomasz Kaczmarek | D5: =VLOOKUP(E5,Treatments!A:G,7,FALSE) -> 90 | E5: 4 | H5: 4 | I5: =VLOOKUP(VLOOKUP(H5,Visits!A:B,2,FALSE),Pets!A:C,3,FALSE) -> kot | J5: =VLOOKUP(H5,Treatments!B:G,6,FALSE) -> 90 | L5: 3 | M5: 3 | N5: =VLOOKUP(M5,Pets!A:B,2,FALSE) -> Bella | O5: =IFERROR(VLOOKUP(L5,Treatments!B:G,6,FALSE),0) -> 30 | P5: =VLOOKUP(M5,Pets!A:C,3,FALSE) -> pies
A6: 5 | B6: 1 | C6: =VLOOKUP(B6,Vets!A:G,7,FALSE) -> Marek Nowak | D6: =VLOOKUP(E6,Treatments!A:G,7,FALSE) -> 150 | E6: 5 | H6: 5 | I6: =VLOOKUP(VLOOKUP(H6,Visits!A:B,2,FALSE),Pets!A:C,3,FALSE) -> chomik | J6: =VLOOKUP(H6,Treatments!B:G,6,FALSE) -> 150 | L6: 4 | M6: 4 | N6: =VLOOKUP(M6,Pets!A:B,2,FALSE) -> Kropka | O6: =IFERROR(VLOOKUP(L6,Treatments!B:G,6,FALSE),0) -> 90 | P6: =VLOOKUP(M6,Pets!A:C,3,FALSE) -> kot
A7: 7 | B7: 4 | C7: =VLOOKUP(B7,Vets!A:G,7,FALSE) -> Anna Wójcik | D7: =VLOOKUP(E7,Treatments!A:G,7,FALSE) -> 15 | E7: 6 | H7: 7 | I7: =VLOOKUP(VLOOKUP(H7,Visits!A:B,2,FALSE),Pets!A:C,3,FALSE) -> kot | J7: =VLOOKUP(H7,Treatments!B:G,6,FALSE) -> 15 | L7: 5 | M7: 5 | N7: =VLOOKUP(M7,Pets!A:B,2,FALSE) -> Kruszynka | O7: =IFERROR(VLOOKUP(L7,Treatments!B:G,6,FALSE),0) -> 150 | P7: =VLOOKUP(M7,Pets!A:C,3,FALSE) -> chomik
A8: 9 | B8: 3 | C8: =VLOOKUP(B8,Vets!A:G,7,FALSE) -> Tomasz Kaczmarek | D8: =VLOOKUP(E8,Treatments!A:G,7,FALSE) -> 110 | E8: 7 | H8: 9 | I8: =VLOOKUP(VLOOKUP(H8,Visits!A:B,2,FALSE),Pets!A:C,3,FALSE) -> pies | J8: =VLOOKUP(H8,Treatments!B:G,6,FALSE) -> 110 | L8: 7 | M8: 7 | N8: =VLOOKUP(M8,Pets!A:B,2,FALSE) -> Puszek | O8: =IFERROR(VLOOKUP(L8,Treatments!B:G,6,FALSE),0) -> 15 | P8: =VLOOKUP(M8,Pets!A:C,3,FALSE) -> kot
A9: 10 | B9: 1 | C9: =VLOOKUP(B9,Vets!A:G,7,FALSE) -> Marek Nowak | D9: =VLOOKUP(E9,Treatments!A:G,7,FALSE) -> 60 | E9: 8 | H9: 10 | I9: =VLOOKUP(VLOOKUP(H9,Visits!A:B,2,FALSE),Pets!A:C,3,FALSE) -> chomik | J9: =VLOOKUP(H9,Treatments!B:G,6,FALSE) -> 60 | L9: 9 | M9: 9 | N9: =VLOOKUP(M9,Pets!A:B,2,FALSE) -> Maks | O9: =IFERROR(VLOOKUP(L9,Treatments!B:G,6,FALSE),0) -> 110 | P9: =VLOOKUP(M9,Pets!A:C,3,FALSE) -> pies
A10: 11 | B10: 5 | C10: =VLOOKUP(B10,Vets!A:G,7,FALSE) -> Paweł Mazur | D10: =VLOOKUP(E10,Treatments!A:G,7,FALSE) -> 50 | E10: 9 | H10: 11 | I10: =VLOOKUP(VLOOKUP(H10,Visits!A:B,2,FALSE),Pets!A:C,3,FALSE) -> chomik | J10: =VLOOKUP(H10,Treatments!B:G,6,FALSE) -> 50 | L10: 10 | M10: 10 | N10: =VLOOKUP(M10,Pets!A:B,2,FALSE) -> Kulka | O10: =IFERROR(VLOOKUP(L10,Treatments!B:G,6,FALSE),0) -> 60 | P10: =VLOOKUP(M10,Pets!A:C,3,FALSE) -> chomik
A11: 12 | B11: 5 | C11: =VLOOKUP(B11,Vets!A:G,7,FALSE) -> Paweł Mazur | D11: =VLOOKUP(E11,Treatments!A:G,7,FALSE) -> 70 | E11: 10 | H11: 12 | I11: =VLOOKUP(VLOOKUP(H11,Visits!A:B,2,FALSE),Pets!A:C,3,FALSE) -> pies | J11: =VLOOKUP(H11,Treatments!B:G,6,FALSE) -> 70 | L11: 11 | M11: 11 | N11: =VLOOKUP(M11,Pets!A:B,2,FALSE) -> Pasztecik | O11: =IFERROR(VLOOKUP(L11,Treatments!B:G,6,FALSE),0) -> 50 | P11: =VLOOKUP(M11,Pets!A:C,3,FALSE) -> chomik
A12: 13 | B12: 1 | C12: =VLOOKUP(B12,Vets!A:G,7,FALSE) -> Marek Nowak | D12: =VLOOKUP(E12,Treatments!A:G,7,FALSE) -> 80 | E12: 11 | H12: 13 | I12: =VLOOKUP(VLOOKUP(H12,Visits!A:B,2,FALSE),Pets!A:C,3,FALSE) -> pies | J12: =VLOOKUP(H12,Treatments!B:G,6,FALSE) -> 80 | L12: 12 | M12: 12 | N12: =VLOOKUP(M12,Pets!A:B,2,FALSE) -> Azor | O12: =IFERROR(VLOOKUP(L12,Treatments!B:G,6,FALSE),0) -> 70 | P12: =VLOOKUP(M12,Pets!A:C,3,FALSE) -> pies
A13: 14 | B13: 3 | C13: =VLOOKUP(B13,Vets!A:G,7,FALSE) -> Tomasz Kaczmarek | D13: =VLOOKUP(E13,Treatments!A:G,7,FALSE) -> 90 | E13: 12 | H13: 14 | I13: =VLOOKUP(VLOOKUP(H13,Visits!A:B,2,FALSE),Pets!A:C,3,FALSE) -> kot | J13: =VLOOKUP(H13,Treatments!B:G,6,FALSE) -> 90 | L13: 13 | M13: 13 | N13: =VLOOKUP(M13,Pets!A:B,2,FALSE) -> Burek | O13: =IFERROR(VLOOKUP(L13,Treatments!B:G,6,FALSE),0) -> 80 | P13: =VLOOKUP(M13,Pets!A:C,3,FALSE) -> pies
A14: 15 | B14: 1 | C14: =VLOOKUP(B14,Vets!A:G,7,FALSE) -> Marek Nowak | D14: =VLOOKUP(E14,Treatments!A:G,7,FALSE) -> 85 | E14: 13 | H14: 15 | I14: =VLOOKUP(VLOOKUP(H14,Visits!A:B,2,FALSE),Pets!A:C,3,FALSE) -> pies | J14: =VLOOKUP(H14,Treatments!B:G,6,FALSE) -> 85 | L14: 14 | M14: 4 | N14: =VLOOKUP(M14,Pets!A:B,2,FALSE) -> Kropka | O14: =IFERROR(VLOOKUP(L14,Treatments!B:G,6,FALSE),0) -> 90 | P14: =VLOOKUP(M14,Pets!A:C,3,FALSE) -> kot
... A148: 154 | B148: 6 | C148: =VLOOKUP(B148,Vets!A:G,7,FALSE) -> Janusz Szymański | D148: =VLOOKUP(E148,Treatments!A:G,7,FALSE) -> 120 | E148: 147 | H148: 154 | I148: =VLOOKUP(VLOOKUP(H148,Visits!A:B,2,FALSE),Pets!A:C,3,FALSE) -> pies | J148: =VLOOKUP(H148,Treatments!B:G,6,FALSE) -> 120 | L148: 153 | M148: 76 | N148: =VLOOKUP(M148,Pets!A:B,2,FALSE) -> Rufi | O148: =IFERROR(VLOOKUP(L148,Treatments!B:G,6,FALSE),0) -> 50 | P148: =VLOOKUP(M148,Pets!A:C,3,FALSE) -> pies
L149: 154 | M149: 78 | N149: =VLOOKUP(M149,Pets!A:B,2,FALSE) -> Nela | O149: =IFERROR(VLOOKUP(L149,Treatments!B:G,6,FALSE),0) -> 120 | P149: =VLOOKUP(M149,Pets!A:C,3,FALSE) -> pies
